<?xml version="1.0" ?>
<!-- =================================================================================== -->
<!-- |    This document was autogenerated by xacro from try.urdf.xacro                 | -->
<!-- |    EDITING THIS FILE BY HAND IS NOT RECOMMENDED                                 | -->
<!-- =================================================================================== -->
<robot name="hand">
  <!-- 1 for right hand, -1 for left hand -->
  <link name="base">
    <visual>
      <origin rpy="0 0 0" xyz="0 0 0"/>
      <geometry>
        <sphere radius="0"/>
      </geometry>
      <material name="solid_color">
        <color rgba="1 1 1 1"/>
      </material>
    </visual>
    <collision>
      <origin rpy="0 0 0" xyz="0 0 0"/>
      <geometry>
        <sphere radius="0"/>
      </geometry>
    </collision>
    <!-- <xacro:unless value="${inertia == 'off'}"> -->
    <inertial>
      <origin rpy="0 0 0" xyz="0 0 0"/>
      <!-- I = 2*m*r^2/5 -->
      <mass value="0"/>
      <inertia ixx="0.0" iyy="0.0" izz="0.0"/>
    </inertial>
    <!-- </xacro:unless> -->
  </link>
  <joint name="joint_base_palm" type="fixed">
    <parent link="base"/>
    <child link="palm"/>
    <origin rpy="0 0 0" xyz="0 0 0"/>
    <axis xyz="1 0 0"/>
    <dynamics damping="0" friction="0"/>
    <limit effort="100.0" lower="-1.5707963267948966" upper="1.5707963267948966" velocity="0.5"/>
  </joint>
  <link name="palm">
    <visual>
      <origin rpy="-1.5707963267948966 0 1.5707963267948966" xyz="0 0.1 -0.3"/>
      <geometry>
        <mesh filename="package://mesh/palm.stl" scale="8.0 9.0 4.0"/>
        <!-- palm.stl -> 1mm ca -->
      </geometry>
      <material name="solid_color">
        <color rgba="1 1 1 1"/>
      </material>
    </visual>
  </link>
  <joint name="joint_palm_thumb_knuckle1_pre" type="fixed">
    <parent link="palm"/>
    <child link="thumb_knuckle1_pre"/>
    <origin rpy="-1.5707963267948966 0 0" xyz="0 0.16666666666666669 0"/>
    <axis xyz="1 0 0"/>
    <dynamics damping="0" friction="0"/>
    <limit effort="100.0" lower="-1.5707963267948966" upper="1.5707963267948966" velocity="0.5"/>
  </joint>
  <link name="thumb_knuckle1_pre">
    <visual>
      <origin rpy="0 0 0" xyz="0 0 0.05"/>
      <geometry>
        <sphere radius="0.05"/>
      </geometry>
      <material name="solid_color">
        <color rgba="1 1 1 1"/>
      </material>
    </visual>
    <collision>
      <origin rpy="0 0 0" xyz="0 0 0.05"/>
      <geometry>
        <sphere radius="0.05"/>
      </geometry>
    </collision>
    <!-- <xacro:unless value="${inertia == 'off'}"> -->
    <inertial>
      <origin rpy="0 0 0" xyz="0 0 0.05"/>
      <!-- I = 2*m*r^2/5 -->
      <mass value="0"/>
      <inertia ixx="0.0" iyy="0.0" izz="0.0"/>
    </inertial>
    <!-- </xacro:unless> -->
  </link>
  <joint name="joint_thumb_knuckle1_pre_thumb_knuckle1" type="revolute">
    <parent link="thumb_knuckle1_pre"/>
    <child link="thumb_knuckle1"/>
    <origin rpy="0 0 0" xyz="0 0 0"/>
    <axis xyz="1 0 0"/>
    <dynamics damping="0" friction="0"/>
    <limit effort="100.0" lower="0" upper="0.5235987755982988" velocity="0.5"/>
  </joint>
  <link name="thumb_knuckle1">
    <visual>
      <origin rpy="0 0 0" xyz="0 0 0.05"/>
      <geometry>
        <sphere radius="0.05"/>
      </geometry>
      <material name="solid_color">
        <color rgba="1 1 1 1"/>
      </material>
    </visual>
    <collision>
      <origin rpy="0 0 0" xyz="0 0 0.05"/>
      <geometry>
        <sphere radius="0.05"/>
      </geometry>
    </collision>
    <!-- <xacro:unless value="${inertia == 'off'}"> -->
    <inertial>
      <origin rpy="0 0 0" xyz="0 0 0.05"/>
      <!-- I = 2*m*r^2/5 -->
      <mass value="0"/>
      <inertia ixx="0.0" iyy="0.0" izz="0.0"/>
    </inertial>
    <!-- </xacro:unless> -->
  </link>
  <joint name="joint_thumb_knuckle1_thumb_phalange1" type="revolute">
    <parent link="thumb_knuckle1"/>
    <child link="thumb_phalange1"/>
    <origin rpy="0" xyz="0 0 0.05"/>
    <axis xyz="0 1 0"/>
    <dynamics damping="0" friction="0"/>
    <limit effort="100.0" lower="0" upper="1.5707963267948966" velocity="0.5"/>
  </joint>
  <link name="thumb_phalange1">
    <visual>
      <origin rpy="0 0 -1.5707963267948966" xyz="0 0.2 0.11499999999999999"/>
      <geometry>
        <mesh filename="package://mesh/thumb0.stl" scale="10.0 7.0 14.0"/>
        <!-- thumb0.stl -> 1mm ca -> 0.001m -->
      </geometry>
      <material name="solid_color">
        <color rgba="1 1 1 1"/>
      </material>
    </visual>
  </link>
  <joint name="joint_thumb_phalange1_thumb_knuckle2" type="fixed">
    <parent link="thumb_phalange1"/>
    <child link="thumb_knuckle2"/>
    <origin rpy="0" xyz="0 0 0.22999999999999998"/>
    <axis xyz="0 1 0"/>
    <dynamics damping="0" friction="0"/>
    <limit effort="100.0" lower="-1.5707963267948966" upper="1.5707963267948966" velocity="0.5"/>
  </joint>
  <link name="thumb_knuckle2">
    <visual>
      <origin rpy="0 0 0" xyz="0 0 0"/>
      <geometry>
        <sphere radius="0.05"/>
      </geometry>
      <material name="solid_color">
        <color rgba="1 1 1 1"/>
      </material>
    </visual>
    <collision>
      <origin rpy="0 0 0" xyz="0 0 0"/>
      <geometry>
        <sphere radius="0.05"/>
      </geometry>
    </collision>
    <!-- <xacro:unless value="${inertia == 'off'}"> -->
    <inertial>
      <origin rpy="0 0 0" xyz="0 0 0"/>
      <!-- I = 2*m*r^2/5 -->
      <mass value="0"/>
      <inertia ixx="0.0" iyy="0.0" izz="0.0"/>
    </inertial>
    <!-- </xacro:unless> -->
  </link>
  <joint name="joint_thumb_knuckle2_thumb_phalange2" type="revolute">
    <parent link="thumb_knuckle2"/>
    <child link="thumb_phalange2"/>
    <origin rpy="0.95097177 0.53406558 -0.34844851" xyz="0 0 0"/>
    <axis xyz="0 1 0"/>
    <dynamics damping="0" friction="0"/>
    <limit effort="100.0" lower="0" upper="1.0471975511965976" velocity="0.5"/>
  </joint>
  <link name="thumb_phalange2">
    <visual>
      <origin rpy="0 0 0" xyz="0 0 0.1"/>
      <geometry>
        <cylinder length="0.2" radius="0.05"/>
      </geometry>
      <material name="solid_color">
        <color rgba="1 1 1 1"/>
      </material>
    </visual>
    <collision>
      <origin rpy="0 0 0" xyz="0 0 0.1"/>
      <geometry>
        <cylinder length="0.2" radius="0.05"/>
      </geometry>
    </collision>
    <!-- <xacro:unless value="${inertia == 'off'}"> -->
    <inertial>
      <origin rpy="0 0 0" xyz="0 0 0.1"/>
      <!-- Ix = Iy = m*(3*r^2 + h^2)/12 and Iz = m*r^2/2-->
      <mass value="1"/>
      <inertia ixx="0.003958333333333334" iyy="0.003958333333333334" izz="0.0012500000000000002"/>
    </inertial>
    <!-- </xacro:unless> -->
  </link>
  <joint name="joint_thumb_phalange2_thumb_knuckle3" type="fixed">
    <parent link="thumb_phalange2"/>
    <child link="thumb_knuckle3"/>
    <origin rpy="0 0 0" xyz="0 0 0.2"/>
    <axis xyz="0 1 0"/>
    <dynamics damping="0" friction="0"/>
    <limit effort="100.0" lower="-1.5707963267948966" upper="1.5707963267948966" velocity="0.5"/>
  </joint>
  <link name="thumb_knuckle3">
    <visual>
      <origin rpy="0 0 0" xyz="0 0 0"/>
      <geometry>
        <sphere radius="0.05"/>
      </geometry>
      <material name="solid_color">
        <color rgba="1 1 1 1"/>
      </material>
    </visual>
    <collision>
      <origin rpy="0 0 0" xyz="0 0 0"/>
      <geometry>
        <sphere radius="0.05"/>
      </geometry>
    </collision>
    <!-- <xacro:unless value="${inertia == 'off'}"> -->
    <inertial>
      <origin rpy="0 0 0" xyz="0 0 0"/>
      <!-- I = 2*m*r^2/5 -->
      <mass value="0"/>
      <inertia ixx="0.0" iyy="0.0" izz="0.0"/>
    </inertial>
    <!-- </xacro:unless> -->
  </link>
  <joint name="joint_thumb_knuckle3_thumb_phalange3" type="revolute">
    <parent link="thumb_knuckle3"/>
    <child link="thumb_phalange3"/>
    <origin rpy="0" xyz="0 0 0"/>
    <axis xyz="0 1 0"/>
    <dynamics damping="0" friction="0"/>
    <limit effort="100.0" lower="0" upper="1.5707963267948966" velocity="0.5"/>
  </joint>
  <link name="thumb_phalange3">
    <visual>
      <origin rpy="0 0 0" xyz="0 0 0.09900000000000002"/>
      <geometry>
        <cylinder length="0.19800000000000004" radius="0.05"/>
      </geometry>
      <material name="solid_color">
        <color rgba="1 1 1 1"/>
      </material>
    </visual>
    <collision>
      <origin rpy="0 0 0" xyz="0 0 0.09900000000000002"/>
      <geometry>
        <cylinder length="0.19800000000000004" radius="0.05"/>
      </geometry>
    </collision>
    <!-- <xacro:unless value="${inertia == 'off'}"> -->
    <inertial>
      <origin rpy="0 0 0" xyz="0 0 0.09900000000000002"/>
      <!-- Ix = Iy = m*(3*r^2 + h^2)/12 and Iz = m*r^2/2-->
      <mass value="1"/>
      <inertia ixx="0.0038920000000000014" iyy="0.0038920000000000014" izz="0.0012500000000000002"/>
    </inertial>
    <!-- </xacro:unless> -->
  </link>
  <joint name="joint_thumb_phalange3_thumb_knuckle4" type="fixed">
    <parent link="thumb_phalange3"/>
    <child link="thumb_knuckle4"/>
    <origin rpy="0" xyz="0 0 0.19800000000000004"/>
    <axis xyz="0 1 0"/>
    <dynamics damping="0" friction="0"/>
    <limit effort="100.0" lower="-1.5707963267948966" upper="1.5707963267948966" velocity="0.5"/>
  </joint>
  <link name="thumb_knuckle4">
    <visual>
      <origin rpy="0 0 0" xyz="0 0 0"/>
      <geometry>
        <sphere radius="0.05"/>
      </geometry>
      <material name="solid_color">
        <color rgba="1 1 1 1"/>
      </material>
    </visual>
    <collision>
      <origin rpy="0 0 0" xyz="0 0 0"/>
      <geometry>
        <sphere radius="0.05"/>
      </geometry>
    </collision>
    <!-- <xacro:unless value="${inertia == 'off'}"> -->
    <inertial>
      <origin rpy="0 0 0" xyz="0 0 0"/>
      <!-- I = 2*m*r^2/5 -->
      <mass value="0"/>
      <inertia ixx="0.0" iyy="0.0" izz="0.0"/>
    </inertial>
    <!-- </xacro:unless> -->
  </link>
  <joint name="joint_palm_index_knuckle1_pre" type="fixed">
    <parent link="palm"/>
    <child link="index_knuckle1_pre"/>
    <origin rpy="0 0 0" xyz="0 0.16666666666666669 0.37666666666666665"/>
    <axis xyz="0 1 0"/>
    <dynamics damping="0" friction="0"/>
    <limit effort="100.0" lower="-1.5707963267948966" upper="1.5707963267948966" velocity="0.5"/>
  </joint>
  <link name="index_knuckle1_pre">
    <visual>
      <origin rpy="0 0 0" xyz="0 0 0.05"/>
      <geometry>
        <sphere radius="0.05"/>
      </geometry>
      <material name="solid_color">
        <color rgba="1 1 1 1"/>
      </material>
    </visual>
    <collision>
      <origin rpy="0 0 0" xyz="0 0 0.05"/>
      <geometry>
        <sphere radius="0.05"/>
      </geometry>
    </collision>
    <!-- <xacro:unless value="${inertia == 'off'}"> -->
    <inertial>
      <origin rpy="0 0 0" xyz="0 0 0.05"/>
      <!-- I = 2*m*r^2/5 -->
      <mass value="0"/>
      <inertia ixx="0.0" iyy="0.0" izz="0.0"/>
    </inertial>
    <!-- </xacro:unless> -->
  </link>
  <joint name="joint_index_knuckle1_pre_index_knuckle1" type="revolute">
    <parent link="index_knuckle1_pre"/>
    <child link="index_knuckle1"/>
    <origin rpy="0 0 0" xyz="0 0 0"/>
    <axis xyz="1 0 0"/>
    <dynamics damping="0" friction="0"/>
    <limit effort="100.0" lower="-0.2617993877991494" upper="0.2617993877991494" velocity="0.5"/>
  </joint>
  <link name="index_knuckle1">
    <visual>
      <origin rpy="0 0 0" xyz="0 0 0.05"/>
      <geometry>
        <sphere radius="0.05"/>
      </geometry>
      <material name="solid_color">
        <color rgba="1 1 1 1"/>
      </material>
    </visual>
    <collision>
      <origin rpy="0 0 0" xyz="0 0 0.05"/>
      <geometry>
        <sphere radius="0.05"/>
      </geometry>
    </collision>
    <!-- <xacro:unless value="${inertia == 'off'}"> -->
    <inertial>
      <origin rpy="0 0 0" xyz="0 0 0.05"/>
      <!-- I = 2*m*r^2/5 -->
      <mass value="0"/>
      <inertia ixx="0.0" iyy="0.0" izz="0.0"/>
    </inertial>
    <!-- </xacro:unless> -->
  </link>
  <joint name="joint_index_knuckle1_index_phalange1" type="revolute">
    <parent link="index_knuckle1"/>
    <child link="index_phalange1"/>
    <origin rpy="0" xyz="0 0 0.05"/>
    <axis xyz="0 1 0"/>
    <dynamics damping="0" friction="0"/>
    <limit effort="100.0" lower="0" upper="1.5707963267948966" velocity="0.5"/>
  </joint>
  <link name="index_phalange1">
    <visual>
      <origin rpy="0 0 0" xyz="0 0 0.1035"/>
      <geometry>
        <cylinder length="0.207" radius="0.05"/>
      </geometry>
      <material name="solid_color">
        <color rgba="1 1 1 1"/>
      </material>
    </visual>
    <collision>
      <origin rpy="0 0 0" xyz="0 0 0.1035"/>
      <geometry>
        <cylinder length="0.207" radius="0.05"/>
      </geometry>
    </collision>
    <!-- <xacro:unless value="${inertia == 'off'}"> -->
    <inertial>
      <origin rpy="0 0 0" xyz="0 0 0.1035"/>
      <!-- Ix = Iy = m*(3*r^2 + h^2)/12 and Iz = m*r^2/2-->
      <mass value="1"/>
      <inertia ixx="0.00419575" iyy="0.00419575" izz="0.0012500000000000002"/>
    </inertial>
    <!-- </xacro:unless> -->
  </link>
  <joint name="joint_index_phalange1_index_knuckle2" type="fixed">
    <parent link="index_phalange1"/>
    <child link="index_knuckle2"/>
    <origin rpy="0" xyz="0 0 0.207"/>
    <axis xyz="0 1 0"/>
    <dynamics damping="0" friction="0"/>
    <limit effort="100.0" lower="-1.5707963267948966" upper="1.5707963267948966" velocity="0.5"/>
  </joint>
  <link name="index_knuckle2">
    <visual>
      <origin rpy="0 0 0" xyz="0 0 0"/>
      <geometry>
        <sphere radius="0.05"/>
      </geometry>
      <material name="solid_color">
        <color rgba="1 1 1 1"/>
      </material>
    </visual>
    <collision>
      <origin rpy="0 0 0" xyz="0 0 0"/>
      <geometry>
        <sphere radius="0.05"/>
      </geometry>
    </collision>
    <!-- <xacro:unless value="${inertia == 'off'}"> -->
    <inertial>
      <origin rpy="0 0 0" xyz="0 0 0"/>
      <!-- I = 2*m*r^2/5 -->
      <mass value="0"/>
      <inertia ixx="0.0" iyy="0.0" izz="0.0"/>
    </inertial>
    <!-- </xacro:unless> -->
  </link>
  <joint name="joint_index_knuckle2_index_phalange2" type="revolute">
    <parent link="index_knuckle2"/>
    <child link="index_phalange2"/>
    <origin rpy="0 0 0" xyz="0 0 0"/>
    <axis xyz="0 1 0"/>
    <dynamics damping="0" friction="0"/>
    <limit effort="100.0" lower="0" upper="1.5707963267948966" velocity="0.5"/>
  </joint>
  <link name="index_phalange2">
    <visual>
      <origin rpy="0 0 0" xyz="0 0 0.09000000000000001"/>
      <geometry>
        <cylinder length="0.18000000000000002" radius="0.05"/>
      </geometry>
      <material name="solid_color">
        <color rgba="1 1 1 1"/>
      </material>
    </visual>
    <collision>
      <origin rpy="0 0 0" xyz="0 0 0.09000000000000001"/>
      <geometry>
        <cylinder length="0.18000000000000002" radius="0.05"/>
      </geometry>
    </collision>
    <!-- <xacro:unless value="${inertia == 'off'}"> -->
    <inertial>
      <origin rpy="0 0 0" xyz="0 0 0.09000000000000001"/>
      <!-- Ix = Iy = m*(3*r^2 + h^2)/12 and Iz = m*r^2/2-->
      <mass value="1"/>
      <inertia ixx="0.0033250000000000003" iyy="0.0033250000000000003" izz="0.0012500000000000002"/>
    </inertial>
    <!-- </xacro:unless> -->
  </link>
  <joint name="joint_index_phalange2_index_knuckle3" type="fixed">
    <parent link="index_phalange2"/>
    <child link="index_knuckle3"/>
    <origin rpy="0 0 0" xyz="0 0 0.18000000000000002"/>
    <axis xyz="0 1 0"/>
    <dynamics damping="0" friction="0"/>
    <limit effort="100.0" lower="-1.5707963267948966" upper="1.5707963267948966" velocity="0.5"/>
  </joint>
  <link name="index_knuckle3">
    <visual>
      <origin rpy="0 0 0" xyz="0 0 0"/>
      <geometry>
        <sphere radius="0.05"/>
      </geometry>
      <material name="solid_color">
        <color rgba="1 1 1 1"/>
      </material>
    </visual>
    <collision>
      <origin rpy="0 0 0" xyz="0 0 0"/>
      <geometry>
        <sphere radius="0.05"/>
      </geometry>
    </collision>
    <!-- <xacro:unless value="${inertia == 'off'}"> -->
    <inertial>
      <origin rpy="0 0 0" xyz="0 0 0"/>
      <!-- I = 2*m*r^2/5 -->
      <mass value="0"/>
      <inertia ixx="0.0" iyy="0.0" izz="0.0"/>
    </inertial>
    <!-- </xacro:unless> -->
  </link>
  <joint name="joint_index_knuckle3_index_phalange3" type="revolute">
    <parent link="index_knuckle3"/>
    <child link="index_phalange3"/>
    <origin rpy="0" xyz="0 0 0"/>
    <axis xyz="0 1 0"/>
    <dynamics damping="0" friction="0"/>
    <limit effort="100.0" lower="0" upper="1.5707963267948966" velocity="0.5"/>
  </joint>
  <link name="index_phalange3">
    <visual>
      <origin rpy="0 0 0" xyz="0 0 0.08100000000000002"/>
      <geometry>
        <cylinder length="0.16200000000000003" radius="0.05"/>
      </geometry>
      <material name="solid_color">
        <color rgba="1 1 1 1"/>
      </material>
    </visual>
    <collision>
      <origin rpy="0 0 0" xyz="0 0 0.08100000000000002"/>
      <geometry>
        <cylinder length="0.16200000000000003" radius="0.05"/>
      </geometry>
    </collision>
    <!-- <xacro:unless value="${inertia == 'off'}"> -->
    <inertial>
      <origin rpy="0 0 0" xyz="0 0 0.08100000000000002"/>
      <!-- Ix = Iy = m*(3*r^2 + h^2)/12 and Iz = m*r^2/2-->
      <mass value="1"/>
      <inertia ixx="0.0028120000000000007" iyy="0.0028120000000000007" izz="0.0012500000000000002"/>
    </inertial>
    <!-- </xacro:unless> -->
  </link>
  <joint name="joint_index_phalange3_index_knuckle4" type="fixed">
    <parent link="index_phalange3"/>
    <child link="index_knuckle4"/>
    <origin rpy="0" xyz="0 0 0.16200000000000003"/>
    <axis xyz="0 1 0"/>
    <dynamics damping="0" friction="0"/>
    <limit effort="100.0" lower="-1.5707963267948966" upper="1.5707963267948966" velocity="0.5"/>
  </joint>
  <link name="index_knuckle4">
    <visual>
      <origin rpy="0 0 0" xyz="0 0 0"/>
      <geometry>
        <sphere radius="0.05"/>
      </geometry>
      <material name="solid_color">
        <color rgba="1 1 1 1"/>
      </material>
    </visual>
    <collision>
      <origin rpy="0 0 0" xyz="0 0 0"/>
      <geometry>
        <sphere radius="0.05"/>
      </geometry>
    </collision>
    <!-- <xacro:unless value="${inertia == 'off'}"> -->
    <inertial>
      <origin rpy="0 0 0" xyz="0 0 0"/>
      <!-- I = 2*m*r^2/5 -->
      <mass value="0"/>
      <inertia ixx="0.0" iyy="0.0" izz="0.0"/>
    </inertial>
    <!-- </xacro:unless> -->
  </link>
  <joint name="joint_palm_middle_knuckle1_pre" type="fixed">
    <parent link="palm"/>
    <child link="middle_knuckle1_pre"/>
    <origin rpy="0 0 0" xyz="0 0.0 0.41"/>
    <axis xyz="0 1 0"/>
    <dynamics damping="0" friction="0"/>
    <limit effort="100.0" lower="-1.5707963267948966" upper="1.5707963267948966" velocity="0.5"/>
  </joint>
  <link name="middle_knuckle1_pre">
    <visual>
      <origin rpy="0 0 0" xyz="0 0 0.05"/>
      <geometry>
        <sphere radius="0.05"/>
      </geometry>
      <material name="solid_color">
        <color rgba="1 1 1 1"/>
      </material>
    </visual>
    <collision>
      <origin rpy="0 0 0" xyz="0 0 0.05"/>
      <geometry>
        <sphere radius="0.05"/>
      </geometry>
    </collision>
    <!-- <xacro:unless value="${inertia == 'off'}"> -->
    <inertial>
      <origin rpy="0 0 0" xyz="0 0 0.05"/>
      <!-- I = 2*m*r^2/5 -->
      <mass value="0"/>
      <inertia ixx="0.0" iyy="0.0" izz="0.0"/>
    </inertial>
    <!-- </xacro:unless> -->
  </link>
  <joint name="joint_middle_knuckle1_pre_middle_knuckle1" type="revolute">
    <parent link="middle_knuckle1_pre"/>
    <child link="middle_knuckle1"/>
    <origin rpy="0 0 0" xyz="0 0 0"/>
    <axis xyz="1 0 0"/>
    <dynamics damping="0" friction="0"/>
    <limit effort="100.0" lower="-0.2617993877991494" upper="0.2617993877991494" velocity="0.5"/>
  </joint>
  <link name="middle_knuckle1">
    <visual>
      <origin rpy="0 0 0" xyz="0 0 0.05"/>
      <geometry>
        <sphere radius="0.05"/>
      </geometry>
      <material name="solid_color">
        <color rgba="1 1 1 1"/>
      </material>
    </visual>
    <collision>
      <origin rpy="0 0 0" xyz="0 0 0.05"/>
      <geometry>
        <sphere radius="0.05"/>
      </geometry>
    </collision>
    <!-- <xacro:unless value="${inertia == 'off'}"> -->
    <inertial>
      <origin rpy="0 0 0" xyz="0 0 0.05"/>
      <!-- I = 2*m*r^2/5 -->
      <mass value="0"/>
      <inertia ixx="0.0" iyy="0.0" izz="0.0"/>
    </inertial>
    <!-- </xacro:unless> -->
  </link>
  <joint name="joint_middle_knuckle1_middle_phalange1" type="revolute">
    <parent link="middle_knuckle1"/>
    <child link="middle_phalange1"/>
    <origin rpy="0" xyz="0 0 0.05"/>
    <axis xyz="0 1 0"/>
    <dynamics damping="0" friction="0"/>
    <limit effort="100.0" lower="0" upper="1.5707963267948966" velocity="0.5"/>
  </joint>
  <link name="middle_phalange1">
    <visual>
      <origin rpy="0 0 0" xyz="0 0 0.11499999999999999"/>
      <geometry>
        <cylinder length="0.22999999999999998" radius="0.05"/>
      </geometry>
      <material name="solid_color">
        <color rgba="1 1 1 1"/>
      </material>
    </visual>
    <collision>
      <origin rpy="0 0 0" xyz="0 0 0.11499999999999999"/>
      <geometry>
        <cylinder length="0.22999999999999998" radius="0.05"/>
      </geometry>
    </collision>
    <!-- <xacro:unless value="${inertia == 'off'}"> -->
    <inertial>
      <origin rpy="0 0 0" xyz="0 0 0.11499999999999999"/>
      <!-- Ix = Iy = m*(3*r^2 + h^2)/12 and Iz = m*r^2/2-->
      <mass value="1"/>
      <inertia ixx="0.005033333333333332" iyy="0.005033333333333332" izz="0.0012500000000000002"/>
    </inertial>
    <!-- </xacro:unless> -->
  </link>
  <joint name="joint_middle_phalange1_middle_knuckle2" type="fixed">
    <parent link="middle_phalange1"/>
    <child link="middle_knuckle2"/>
    <origin rpy="0" xyz="0 0 0.22999999999999998"/>
    <axis xyz="0 1 0"/>
    <dynamics damping="0" friction="0"/>
    <limit effort="100.0" lower="-1.5707963267948966" upper="1.5707963267948966" velocity="0.5"/>
  </joint>
  <link name="middle_knuckle2">
    <visual>
      <origin rpy="0 0 0" xyz="0 0 0"/>
      <geometry>
        <sphere radius="0.05"/>
      </geometry>
      <material name="solid_color">
        <color rgba="1 1 1 1"/>
      </material>
    </visual>
    <collision>
      <origin rpy="0 0 0" xyz="0 0 0"/>
      <geometry>
        <sphere radius="0.05"/>
      </geometry>
    </collision>
    <!-- <xacro:unless value="${inertia == 'off'}"> -->
    <inertial>
      <origin rpy="0 0 0" xyz="0 0 0"/>
      <!-- I = 2*m*r^2/5 -->
      <mass value="0"/>
      <inertia ixx="0.0" iyy="0.0" izz="0.0"/>
    </inertial>
    <!-- </xacro:unless> -->
  </link>
  <joint name="joint_middle_knuckle2_middle_phalange2" type="revolute">
    <parent link="middle_knuckle2"/>
    <child link="middle_phalange2"/>
    <origin rpy="0 0 0" xyz="0 0 0"/>
    <axis xyz="0 1 0"/>
    <dynamics damping="0" friction="0"/>
    <limit effort="100.0" lower="0" upper="1.5707963267948966" velocity="0.5"/>
  </joint>
  <link name="middle_phalange2">
    <visual>
      <origin rpy="0 0 0" xyz="0 0 0.1"/>
      <geometry>
        <cylinder length="0.2" radius="0.05"/>
      </geometry>
      <material name="solid_color">
        <color rgba="1 1 1 1"/>
      </material>
    </visual>
    <collision>
      <origin rpy="0 0 0" xyz="0 0 0.1"/>
      <geometry>
        <cylinder length="0.2" radius="0.05"/>
      </geometry>
    </collision>
    <!-- <xacro:unless value="${inertia == 'off'}"> -->
    <inertial>
      <origin rpy="0 0 0" xyz="0 0 0.1"/>
      <!-- Ix = Iy = m*(3*r^2 + h^2)/12 and Iz = m*r^2/2-->
      <mass value="1"/>
      <inertia ixx="0.003958333333333334" iyy="0.003958333333333334" izz="0.0012500000000000002"/>
    </inertial>
    <!-- </xacro:unless> -->
  </link>
  <joint name="joint_middle_phalange2_middle_knuckle3" type="fixed">
    <parent link="middle_phalange2"/>
    <child link="middle_knuckle3"/>
    <origin rpy="0 0 0" xyz="0 0 0.2"/>
    <axis xyz="0 1 0"/>
    <dynamics damping="0" friction="0"/>
    <limit effort="100.0" lower="-1.5707963267948966" upper="1.5707963267948966" velocity="0.5"/>
  </joint>
  <link name="middle_knuckle3">
    <visual>
      <origin rpy="0 0 0" xyz="0 0 0"/>
      <geometry>
        <sphere radius="0.05"/>
      </geometry>
      <material name="solid_color">
        <color rgba="1 1 1 1"/>
      </material>
    </visual>
    <collision>
      <origin rpy="0 0 0" xyz="0 0 0"/>
      <geometry>
        <sphere radius="0.05"/>
      </geometry>
    </collision>
    <!-- <xacro:unless value="${inertia == 'off'}"> -->
    <inertial>
      <origin rpy="0 0 0" xyz="0 0 0"/>
      <!-- I = 2*m*r^2/5 -->
      <mass value="0"/>
      <inertia ixx="0.0" iyy="0.0" izz="0.0"/>
    </inertial>
    <!-- </xacro:unless> -->
  </link>
  <joint name="joint_middle_knuckle3_middle_phalange3" type="revolute">
    <parent link="middle_knuckle3"/>
    <child link="middle_phalange3"/>
    <origin rpy="0" xyz="0 0 0"/>
    <axis xyz="0 1 0"/>
    <dynamics damping="0" friction="0"/>
    <limit effort="100.0" lower="0" upper="1.5707963267948966" velocity="0.5"/>
  </joint>
  <link name="middle_phalange3">
    <visual>
      <origin rpy="0 0 0" xyz="0 0 0.09000000000000001"/>
      <geometry>
        <cylinder length="0.18000000000000002" radius="0.05"/>
      </geometry>
      <material name="solid_color">
        <color rgba="1 1 1 1"/>
      </material>
    </visual>
    <collision>
      <origin rpy="0 0 0" xyz="0 0 0.09000000000000001"/>
      <geometry>
        <cylinder length="0.18000000000000002" radius="0.05"/>
      </geometry>
    </collision>
    <!-- <xacro:unless value="${inertia == 'off'}"> -->
    <inertial>
      <origin rpy="0 0 0" xyz="0 0 0.09000000000000001"/>
      <!-- Ix = Iy = m*(3*r^2 + h^2)/12 and Iz = m*r^2/2-->
      <mass value="1"/>
      <inertia ixx="0.0033250000000000003" iyy="0.0033250000000000003" izz="0.0012500000000000002"/>
    </inertial>
    <!-- </xacro:unless> -->
  </link>
  <joint name="joint_middle_phalange3_middle_knuckle4" type="fixed">
    <parent link="middle_phalange3"/>
    <child link="middle_knuckle4"/>
    <origin rpy="0" xyz="0 0 0.18000000000000002"/>
    <axis xyz="0 1 0"/>
    <dynamics damping="0" friction="0"/>
    <limit effort="100.0" lower="-1.5707963267948966" upper="1.5707963267948966" velocity="0.5"/>
  </joint>
  <link name="middle_knuckle4">
    <visual>
      <origin rpy="0 0 0" xyz="0 0 0"/>
      <geometry>
        <sphere radius="0.05"/>
      </geometry>
      <material name="solid_color">
        <color rgba="1 1 1 1"/>
      </material>
    </visual>
    <collision>
      <origin rpy="0 0 0" xyz="0 0 0"/>
      <geometry>
        <sphere radius="0.05"/>
      </geometry>
    </collision>
    <!-- <xacro:unless value="${inertia == 'off'}"> -->
    <inertial>
      <origin rpy="0 0 0" xyz="0 0 0"/>
      <!-- I = 2*m*r^2/5 -->
      <mass value="0"/>
      <inertia ixx="0.0" iyy="0.0" izz="0.0"/>
    </inertial>
    <!-- </xacro:unless> -->
  </link>
  <joint name="joint_palm_ring_knuckle1_pre" type="fixed">
    <parent link="palm"/>
    <child link="ring_knuckle1_pre"/>
    <origin rpy="0 0 0" xyz="0 -0.16666666666666669 0.34333333333333327"/>
    <axis xyz="0 1 0"/>
    <dynamics damping="0" friction="0"/>
    <limit effort="100.0" lower="-1.5707963267948966" upper="1.5707963267948966" velocity="0.5"/>
  </joint>
  <link name="ring_knuckle1_pre">
    <visual>
      <origin rpy="0 0 0" xyz="0 0 0.05"/>
      <geometry>
        <sphere radius="0.05"/>
      </geometry>
      <material name="solid_color">
        <color rgba="1 1 1 1"/>
      </material>
    </visual>
    <collision>
      <origin rpy="0 0 0" xyz="0 0 0.05"/>
      <geometry>
        <sphere radius="0.05"/>
      </geometry>
    </collision>
    <!-- <xacro:unless value="${inertia == 'off'}"> -->
    <inertial>
      <origin rpy="0 0 0" xyz="0 0 0.05"/>
      <!-- I = 2*m*r^2/5 -->
      <mass value="0"/>
      <inertia ixx="0.0" iyy="0.0" izz="0.0"/>
    </inertial>
    <!-- </xacro:unless> -->
  </link>
  <joint name="joint_ring_knuckle1_pre_ring_knuckle1" type="revolute">
    <parent link="ring_knuckle1_pre"/>
    <child link="ring_knuckle1"/>
    <origin rpy="0 0 0" xyz="0 0 0"/>
    <axis xyz="1 0 0"/>
    <dynamics damping="0" friction="0"/>
    <limit effort="100.0" lower="-0.2617993877991494" upper="0.2617993877991494" velocity="0.5"/>
  </joint>
  <link name="ring_knuckle1">
    <visual>
      <origin rpy="0 0 0" xyz="0 0 0.05"/>
      <geometry>
        <sphere radius="0.05"/>
      </geometry>
      <material name="solid_color">
        <color rgba="1 1 1 1"/>
      </material>
    </visual>
    <collision>
      <origin rpy="0 0 0" xyz="0 0 0.05"/>
      <geometry>
        <sphere radius="0.05"/>
      </geometry>
    </collision>
    <!-- <xacro:unless value="${inertia == 'off'}"> -->
    <inertial>
      <origin rpy="0 0 0" xyz="0 0 0.05"/>
      <!-- I = 2*m*r^2/5 -->
      <mass value="0"/>
      <inertia ixx="0.0" iyy="0.0" izz="0.0"/>
    </inertial>
    <!-- </xacro:unless> -->
  </link>
  <joint name="joint_ring_knuckle1_ring_phalange1" type="revolute">
    <parent link="ring_knuckle1"/>
    <child link="ring_phalange1"/>
    <origin rpy="0" xyz="0 0 0.05"/>
    <axis xyz="0 1 0"/>
    <dynamics damping="0" friction="0"/>
    <limit effort="100.0" lower="0" upper="1.5707963267948966" velocity="0.5"/>
  </joint>
  <link name="ring_phalange1">
    <visual>
      <origin rpy="0 0 0" xyz="0 0 0.09774999999999999"/>
      <geometry>
        <cylinder length="0.19549999999999998" radius="0.05"/>
      </geometry>
      <material name="solid_color">
        <color rgba="1 1 1 1"/>
      </material>
    </visual>
    <collision>
      <origin rpy="0 0 0" xyz="0 0 0.09774999999999999"/>
      <geometry>
        <cylinder length="0.19549999999999998" radius="0.05"/>
      </geometry>
    </collision>
    <!-- <xacro:unless value="${inertia == 'off'}"> -->
    <inertial>
      <origin rpy="0 0 0" xyz="0 0 0.09774999999999999"/>
      <!-- Ix = Iy = m*(3*r^2 + h^2)/12 and Iz = m*r^2/2-->
      <mass value="1"/>
      <inertia ixx="0.0038100208333333324" iyy="0.0038100208333333324" izz="0.0012500000000000002"/>
    </inertial>
    <!-- </xacro:unless> -->
  </link>
  <joint name="joint_ring_phalange1_ring_knuckle2" type="fixed">
    <parent link="ring_phalange1"/>
    <child link="ring_knuckle2"/>
    <origin rpy="0" xyz="0 0 0.19549999999999998"/>
    <axis xyz="0 1 0"/>
    <dynamics damping="0" friction="0"/>
    <limit effort="100.0" lower="-1.5707963267948966" upper="1.5707963267948966" velocity="0.5"/>
  </joint>
  <link name="ring_knuckle2">
    <visual>
      <origin rpy="0 0 0" xyz="0 0 0"/>
      <geometry>
        <sphere radius="0.05"/>
      </geometry>
      <material name="solid_color">
        <color rgba="1 1 1 1"/>
      </material>
    </visual>
    <collision>
      <origin rpy="0 0 0" xyz="0 0 0"/>
      <geometry>
        <sphere radius="0.05"/>
      </geometry>
    </collision>
    <!-- <xacro:unless value="${inertia == 'off'}"> -->
    <inertial>
      <origin rpy="0 0 0" xyz="0 0 0"/>
      <!-- I = 2*m*r^2/5 -->
      <mass value="0"/>
      <inertia ixx="0.0" iyy="0.0" izz="0.0"/>
    </inertial>
    <!-- </xacro:unless> -->
  </link>
  <joint name="joint_ring_knuckle2_ring_phalange2" type="revolute">
    <parent link="ring_knuckle2"/>
    <child link="ring_phalange2"/>
    <origin rpy="0 0 0" xyz="0 0 0"/>
    <axis xyz="0 1 0"/>
    <dynamics damping="0" friction="0"/>
    <limit effort="100.0" lower="0" upper="1.5707963267948966" velocity="0.5"/>
  </joint>
  <link name="ring_phalange2">
    <visual>
      <origin rpy="0 0 0" xyz="0 0 0.085"/>
      <geometry>
        <cylinder length="0.17" radius="0.05"/>
      </geometry>
      <material name="solid_color">
        <color rgba="1 1 1 1"/>
      </material>
    </visual>
    <collision>
      <origin rpy="0 0 0" xyz="0 0 0.085"/>
      <geometry>
        <cylinder length="0.17" radius="0.05"/>
      </geometry>
    </collision>
    <!-- <xacro:unless value="${inertia == 'off'}"> -->
    <inertial>
      <origin rpy="0 0 0" xyz="0 0 0.085"/>
      <!-- Ix = Iy = m*(3*r^2 + h^2)/12 and Iz = m*r^2/2-->
      <mass value="1"/>
      <inertia ixx="0.003033333333333334" iyy="0.003033333333333334" izz="0.0012500000000000002"/>
    </inertial>
    <!-- </xacro:unless> -->
  </link>
  <joint name="joint_ring_phalange2_ring_knuckle3" type="fixed">
    <parent link="ring_phalange2"/>
    <child link="ring_knuckle3"/>
    <origin rpy="0 0 0" xyz="0 0 0.17"/>
    <axis xyz="0 1 0"/>
    <dynamics damping="0" friction="0"/>
    <limit effort="100.0" lower="-1.5707963267948966" upper="1.5707963267948966" velocity="0.5"/>
  </joint>
  <link name="ring_knuckle3">
    <visual>
      <origin rpy="0 0 0" xyz="0 0 0"/>
      <geometry>
        <sphere radius="0.05"/>
      </geometry>
      <material name="solid_color">
        <color rgba="1 1 1 1"/>
      </material>
    </visual>
    <collision>
      <origin rpy="0 0 0" xyz="0 0 0"/>
      <geometry>
        <sphere radius="0.05"/>
      </geometry>
    </collision>
    <!-- <xacro:unless value="${inertia == 'off'}"> -->
    <inertial>
      <origin rpy="0 0 0" xyz="0 0 0"/>
      <!-- I = 2*m*r^2/5 -->
      <mass value="0"/>
      <inertia ixx="0.0" iyy="0.0" izz="0.0"/>
    </inertial>
    <!-- </xacro:unless> -->
  </link>
  <joint name="joint_ring_knuckle3_ring_phalange3" type="revolute">
    <parent link="ring_knuckle3"/>
    <child link="ring_phalange3"/>
    <origin rpy="0" xyz="0 0 0"/>
    <axis xyz="0 1 0"/>
    <dynamics damping="0" friction="0"/>
    <limit effort="100.0" lower="0" upper="1.5707963267948966" velocity="0.5"/>
  </joint>
  <link name="ring_phalange3">
    <visual>
      <origin rpy="0 0 0" xyz="0 0 0.07650000000000001"/>
      <geometry>
        <cylinder length="0.15300000000000002" radius="0.05"/>
      </geometry>
      <material name="solid_color">
        <color rgba="1 1 1 1"/>
      </material>
    </visual>
    <collision>
      <origin rpy="0 0 0" xyz="0 0 0.07650000000000001"/>
      <geometry>
        <cylinder length="0.15300000000000002" radius="0.05"/>
      </geometry>
    </collision>
    <!-- <xacro:unless value="${inertia == 'off'}"> -->
    <inertial>
      <origin rpy="0 0 0" xyz="0 0 0.07650000000000001"/>
      <!-- Ix = Iy = m*(3*r^2 + h^2)/12 and Iz = m*r^2/2-->
      <mass value="1"/>
      <inertia ixx="0.0025757500000000003" iyy="0.0025757500000000003" izz="0.0012500000000000002"/>
    </inertial>
    <!-- </xacro:unless> -->
  </link>
  <joint name="joint_ring_phalange3_ring_knuckle4" type="fixed">
    <parent link="ring_phalange3"/>
    <child link="ring_knuckle4"/>
    <origin rpy="0" xyz="0 0 0.15300000000000002"/>
    <axis xyz="0 1 0"/>
    <dynamics damping="0" friction="0"/>
    <limit effort="100.0" lower="-1.5707963267948966" upper="1.5707963267948966" velocity="0.5"/>
  </joint>
  <link name="ring_knuckle4">
    <visual>
      <origin rpy="0 0 0" xyz="0 0 0"/>
      <geometry>
        <sphere radius="0.05"/>
      </geometry>
      <material name="solid_color">
        <color rgba="1 1 1 1"/>
      </material>
    </visual>
    <collision>
      <origin rpy="0 0 0" xyz="0 0 0"/>
      <geometry>
        <sphere radius="0.05"/>
      </geometry>
    </collision>
    <!-- <xacro:unless value="${inertia == 'off'}"> -->
    <inertial>
      <origin rpy="0 0 0" xyz="0 0 0"/>
      <!-- I = 2*m*r^2/5 -->
      <mass value="0"/>
      <inertia ixx="0.0" iyy="0.0" izz="0.0"/>
    </inertial>
    <!-- </xacro:unless> -->
  </link>
  <joint name="joint_palm_little_knuckle1_pre" type="fixed">
    <parent link="palm"/>
    <child link="little_knuckle1_pre"/>
    <origin rpy="0 0 0" xyz="0 -0.33333333333333337 0.2433333333333333"/>
    <axis xyz="0 1 0"/>
    <dynamics damping="0" friction="0"/>
    <limit effort="100.0" lower="-1.5707963267948966" upper="1.5707963267948966" velocity="0.5"/>
  </joint>
  <link name="little_knuckle1_pre">
    <visual>
      <origin rpy="0 0 0" xyz="0 0 0.05"/>
      <geometry>
        <sphere radius="0.05"/>
      </geometry>
      <material name="solid_color">
        <color rgba="1 1 1 1"/>
      </material>
    </visual>
    <collision>
      <origin rpy="0 0 0" xyz="0 0 0.05"/>
      <geometry>
        <sphere radius="0.05"/>
      </geometry>
    </collision>
    <!-- <xacro:unless value="${inertia == 'off'}"> -->
    <inertial>
      <origin rpy="0 0 0" xyz="0 0 0.05"/>
      <!-- I = 2*m*r^2/5 -->
      <mass value="0"/>
      <inertia ixx="0.0" iyy="0.0" izz="0.0"/>
    </inertial>
    <!-- </xacro:unless> -->
  </link>
  <joint name="joint_little_knuckle1_pre_little_knuckle1" type="revolute">
    <parent link="little_knuckle1_pre"/>
    <child link="little_knuckle1"/>
    <origin rpy="0 0 0" xyz="0 0 0"/>
    <axis xyz="1 0 0"/>
    <dynamics damping="0" friction="0"/>
    <limit effort="100.0" lower="-0.2617993877991494" upper="0.5235987755982988" velocity="0.5"/>
  </joint>
  <link name="little_knuckle1">
    <visual>
      <origin rpy="0 0 0" xyz="0 0 0.05"/>
      <geometry>
        <sphere radius="0.05"/>
      </geometry>
      <material name="solid_color">
        <color rgba="1 1 1 1"/>
      </material>
    </visual>
    <collision>
      <origin rpy="0 0 0" xyz="0 0 0.05"/>
      <geometry>
        <sphere radius="0.05"/>
      </geometry>
    </collision>
    <!-- <xacro:unless value="${inertia == 'off'}"> -->
    <inertial>
      <origin rpy="0 0 0" xyz="0 0 0.05"/>
      <!-- I = 2*m*r^2/5 -->
      <mass value="0"/>
      <inertia ixx="0.0" iyy="0.0" izz="0.0"/>
    </inertial>
    <!-- </xacro:unless> -->
  </link>
  <joint name="joint_little_knuckle1_little_phalange1" type="revolute">
    <parent link="little_knuckle1"/>
    <child link="little_phalange1"/>
    <origin rpy="0" xyz="0 0 0.05"/>
    <axis xyz="0 1 0"/>
    <dynamics damping="0" friction="0"/>
    <limit effort="100.0" lower="0" upper="1.5707963267948966" velocity="0.5"/>
  </joint>
  <link name="little_phalange1">
    <visual>
      <origin rpy="0 0 0" xyz="0 0 0.08049999999999999"/>
      <geometry>
        <cylinder length="0.16099999999999998" radius="0.05"/>
      </geometry>
      <material name="solid_color">
        <color rgba="1 1 1 1"/>
      </material>
    </visual>
    <collision>
      <origin rpy="0 0 0" xyz="0 0 0.08049999999999999"/>
      <geometry>
        <cylinder length="0.16099999999999998" radius="0.05"/>
      </geometry>
    </collision>
    <!-- <xacro:unless value="${inertia == 'off'}"> -->
    <inertial>
      <origin rpy="0 0 0" xyz="0 0 0.08049999999999999"/>
      <!-- Ix = Iy = m*(3*r^2 + h^2)/12 and Iz = m*r^2/2-->
      <mass value="1"/>
      <inertia ixx="0.0027850833333333326" iyy="0.0027850833333333326" izz="0.0012500000000000002"/>
    </inertial>
    <!-- </xacro:unless> -->
  </link>
  <joint name="joint_little_phalange1_little_knuckle2" type="fixed">
    <parent link="little_phalange1"/>
    <child link="little_knuckle2"/>
    <origin rpy="0" xyz="0 0 0.16099999999999998"/>
    <axis xyz="0 1 0"/>
    <dynamics damping="0" friction="0"/>
    <limit effort="100.0" lower="-1.5707963267948966" upper="1.5707963267948966" velocity="0.5"/>
  </joint>
  <link name="little_knuckle2">
    <visual>
      <origin rpy="0 0 0" xyz="0 0 0"/>
      <geometry>
        <sphere radius="0.05"/>
      </geometry>
      <material name="solid_color">
        <color rgba="1 1 1 1"/>
      </material>
    </visual>
    <collision>
      <origin rpy="0 0 0" xyz="0 0 0"/>
      <geometry>
        <sphere radius="0.05"/>
      </geometry>
    </collision>
    <!-- <xacro:unless value="${inertia == 'off'}"> -->
    <inertial>
      <origin rpy="0 0 0" xyz="0 0 0"/>
      <!-- I = 2*m*r^2/5 -->
      <mass value="0"/>
      <inertia ixx="0.0" iyy="0.0" izz="0.0"/>
    </inertial>
    <!-- </xacro:unless> -->
  </link>
  <joint name="joint_little_knuckle2_little_phalange2" type="revolute">
    <parent link="little_knuckle2"/>
    <child link="little_phalange2"/>
    <origin rpy="0 0 0" xyz="0 0 0"/>
    <axis xyz="0 1 0"/>
    <dynamics damping="0" friction="0"/>
    <limit effort="100.0" lower="0" upper="1.5707963267948966" velocity="0.5"/>
  </joint>
  <link name="little_phalange2">
    <visual>
      <origin rpy="0 0 0" xyz="0 0 0.06999999999999999"/>
      <geometry>
        <cylinder length="0.13999999999999999" radius="0.05"/>
      </geometry>
      <material name="solid_color">
        <color rgba="1 1 1 1"/>
      </material>
    </visual>
    <collision>
      <origin rpy="0 0 0" xyz="0 0 0.06999999999999999"/>
      <geometry>
        <cylinder length="0.13999999999999999" radius="0.05"/>
      </geometry>
    </collision>
    <!-- <xacro:unless value="${inertia == 'off'}"> -->
    <inertial>
      <origin rpy="0 0 0" xyz="0 0 0.06999999999999999"/>
      <!-- Ix = Iy = m*(3*r^2 + h^2)/12 and Iz = m*r^2/2-->
      <mass value="1"/>
      <inertia ixx="0.002258333333333333" iyy="0.002258333333333333" izz="0.0012500000000000002"/>
    </inertial>
    <!-- </xacro:unless> -->
  </link>
  <joint name="joint_little_phalange2_little_knuckle3" type="fixed">
    <parent link="little_phalange2"/>
    <child link="little_knuckle3"/>
    <origin rpy="0 0 0" xyz="0 0 0.13999999999999999"/>
    <axis xyz="0 1 0"/>
    <dynamics damping="0" friction="0"/>
    <limit effort="100.0" lower="-1.5707963267948966" upper="1.5707963267948966" velocity="0.5"/>
  </joint>
  <link name="little_knuckle3">
    <visual>
      <origin rpy="0 0 0" xyz="0 0 0"/>
      <geometry>
        <sphere radius="0.05"/>
      </geometry>
      <material name="solid_color">
        <color rgba="1 1 1 1"/>
      </material>
    </visual>
    <collision>
      <origin rpy="0 0 0" xyz="0 0 0"/>
      <geometry>
        <sphere radius="0.05"/>
      </geometry>
    </collision>
    <!-- <xacro:unless value="${inertia == 'off'}"> -->
    <inertial>
      <origin rpy="0 0 0" xyz="0 0 0"/>
      <!-- I = 2*m*r^2/5 -->
      <mass value="0"/>
      <inertia ixx="0.0" iyy="0.0" izz="0.0"/>
    </inertial>
    <!-- </xacro:unless> -->
  </link>
  <joint name="joint_little_knuckle3_little_phalange3" type="revolute">
    <parent link="little_knuckle3"/>
    <child link="little_phalange3"/>
    <origin rpy="0" xyz="0 0 0"/>
    <axis xyz="0 1 0"/>
    <dynamics damping="0" friction="0"/>
    <limit effort="100.0" lower="0" upper="1.5707963267948966" velocity="0.5"/>
  </joint>
  <link name="little_phalange3">
    <visual>
      <origin rpy="0 0 0" xyz="0 0 0.063"/>
      <geometry>
        <cylinder length="0.126" radius="0.05"/>
      </geometry>
      <material name="solid_color">
        <color rgba="1 1 1 1"/>
      </material>
    </visual>
    <collision>
      <origin rpy="0 0 0" xyz="0 0 0.063"/>
      <geometry>
        <cylinder length="0.126" radius="0.05"/>
      </geometry>
    </collision>
    <!-- <xacro:unless value="${inertia == 'off'}"> -->
    <inertial>
      <origin rpy="0 0 0" xyz="0 0 0.063"/>
      <!-- Ix = Iy = m*(3*r^2 + h^2)/12 and Iz = m*r^2/2-->
      <mass value="1"/>
      <inertia ixx="0.001948" iyy="0.001948" izz="0.0012500000000000002"/>
    </inertial>
    <!-- </xacro:unless> -->
  </link>
  <joint name="joint_little_phalange3_little_knuckle4" type="fixed">
    <parent link="little_phalange3"/>
    <child link="little_knuckle4"/>
    <origin rpy="0" xyz="0 0 0.126"/>
    <axis xyz="0 1 0"/>
    <dynamics damping="0" friction="0"/>
    <limit effort="100.0" lower="-1.5707963267948966" upper="1.5707963267948966" velocity="0.5"/>
  </joint>
  <link name="little_knuckle4">
    <visual>
      <origin rpy="0 0 0" xyz="0 0 0"/>
      <geometry>
        <sphere radius="0.05"/>
      </geometry>
      <material name="solid_color">
        <color rgba="1 1 1 1"/>
      </material>
    </visual>
    <collision>
      <origin rpy="0 0 0" xyz="0 0 0"/>
      <geometry>
        <sphere radius="0.05"/>
      </geometry>
    </collision>
    <!-- <xacro:unless value="${inertia == 'off'}"> -->
    <inertial>
      <origin rpy="0 0 0" xyz="0 0 0"/>
      <!-- I = 2*m*r^2/5 -->
      <mass value="0"/>
      <inertia ixx="0.0" iyy="0.0" izz="0.0"/>
    </inertial>
    <!-- </xacro:unless> -->
  </link>
</robot>